<?xml version="1.0"?>
<robot name="argon_base" xmlns:xacro="http://ros.org/wiki/xacro">
  <xacro:include filename="$(find argon_description)/urdf/common_properties.xacro"/>

  <xacro:property name="argon_base_center_x" value="0.0" />
  <xacro:property name="argon_base_center_y" value="0.0" />
  <xacro:property name="argon_base_center_z" value="0.040" />

  <xacro:property name="argon_base_wheel_offset_x" value="0.0725" />
  <xacro:property name="argon_base_wheel_offset_y" value="0.0645" />
  <xacro:property name="argon_base_wheel_offset_z" value="0.010" />
  <xacro:property name="argon_base_wheel_radius" value="0.03" />
  <xacro:property name="argon_base_wheel_length" value="0.032" />

  <link name="base_footprint"/>

  <joint name="base_joint" type="fixed">
    <parent link="base_footprint"/>
    <child link="base_link"/>
    <origin xyz="${argon_base_center_x} ${argon_base_center_y} ${argon_base_center_z}" rpy="0 0 0"/>
  </joint>

  <link name="base_link">
    <visual>
      <origin xyz="0 0 0" rpy="0 0 0" />
      <geometry>
        <mesh filename="package://argon_description/meshes/argon_base.STL" />
      </geometry>
      <material name="orange"/>
    </visual>

    <collision>
      <geometry>
        <mesh filename="package://argon_description/meshes/argon_base.STL" />
      </geometry>
    </collision>

  </link>

  <xacro:macro name="wheel" params="wheel_name offset_x offset_y offset_z">

    <joint name="wheel_${wheel_name}_joint" type="continuous">
      <parent link="base_link"/>
      <child link="wheel_${wheel_name}_link"/>
      <origin xyz="${offset_x} ${offset_y} ${offset_z}" rpy="0 0 0"/>
      <axis xyz="0 1 0"/>
    </joint>

    <link name="wheel_${wheel_name}_link">
      <visual>
        <origin xyz="0 0 0" rpy="${M_PI*0.5} 0 0"/>
        <geometry>
          <cylinder length="${argon_base_wheel_length}" radius="${argon_base_wheel_radius}"/>
        </geometry>
        <material name="black"/>
      </visual>
      <collision>
        <geometry>
          <cylinder length="${argon_base_wheel_length}" radius="${argon_base_wheel_radius}"/>
        </geometry>
      </collision>
    </link>

  </xacro:macro>

  <xacro:wheel wheel_name="front_left" offset_x="${argon_base_wheel_offset_x}" offset_y="${argon_base_wheel_offset_y}" offset_z="${-argon_base_wheel_offset_z}"/>
  <xacro:wheel wheel_name="front_right" offset_x="${argon_base_wheel_offset_x}" offset_y="${-argon_base_wheel_offset_y}" offset_z="${-argon_base_wheel_offset_z}"/>
  <xacro:wheel wheel_name="rear_left" offset_x="${-argon_base_wheel_offset_x}" offset_y="${argon_base_wheel_offset_y}" offset_z="${-argon_base_wheel_offset_z}"/>
  <xacro:wheel wheel_name="rear_right" offset_x="${-argon_base_wheel_offset_x}" offset_y="${-argon_base_wheel_offset_y}" offset_z="${-argon_base_wheel_offset_z}"/>

</robot>
